Workbook

Sheet Liikkeet
A1: Liike | B1: Osoite | C1: Postiosoite | D1: Kaupunki | E1: Verkkosivu | F1: Latitude | G1: Longitude
A2: Fonum | B2: Aleksanterinkatu 18 | C2: 15140 | D2: Lahti | E2: https://www.fonum.fi/ | F2: 60.982613 | G2: 25.663280
A3: Handleit | B3: Vapaudenkatu 9 | C3: 15110 | D3: Lahti | E3: https://www.handle-it.fi/ | F3: 60.983812 | G3: 25.658643
A4: itapsa | B4: Ajokatu 55 | C4: 15500 | D4: Lahti | E4: https://itapsa.com/myymala/lahti/ | F4: 60.963646 | G4: 25.657684
A5: Lahden ATK klinikka | B5: Vapaudenkatu 18 | C5: 15110 | D5: Lahti | E5: https://lahdenatk.fi/ | F5: 60.983869 | G5: 25.660017
A6: Puhelinhuolto | B6: Pasaasi 2 | C6: 15700 | D6: Lahti | E6: https://puhelinhuolto.fi/ | F6: 60.934333 | G6: 25.624150

Sheet Puhelin merkki ja malli
A1: Merkki | B1: Malli
A2: Apple | B2: iPhone 15 Pro 5G
A3: Apple | B3: iPhone 15 Pro 5G
A4: Apple | B4: iPhone 15 Pro 5G
A5: Apple | B5: iPhone 13 5G
A6: Apple | B6: iPhone 13 5G
A7: Apple | B7: iPhone 13 5G
A8: Honor | B8: X6a
A9: Honor | B9: X6a
A10: Honor | B10: X6a
A11: OnePlus | B11: Nord CE4 Lite 5G
A12: OnePlus | B12: Nord CE4 Lite 5G
... A31: Samsung | B31: Galaxy A15 5G

Sheet Puhelin tuotehinta
A1: Maker | B1: Model | C1: Näyttö | D1: Akku | E1: Latausportti
A2: Apple | B2: iPhone 15 Pro 5G | C2: 330 | D2: 27 | E2: 38
A3: Apple | B3: iPhone 13 5G | C3: 181 | D3: 27 | E3: 21
A4: Honor | B4: X6a | C4: 40 | D4: 19 | E4: 23
A5: OnePlus | B5: Nord CE4 Lite 5G | C5: 88 | D5: 12 | E5: 15
A6: OnePlus | B6: Nord CE 3 Lite 5G | C6: 40 | D6: 10 | E6: 15
A7: OnePlus | B7: 12 5G | C7: 176 | D7: 14 | E7: 15
A8: Oppo | B8: A18 | C8: 16 | D8: 17 | E8: 17
A9: Samsung | B9: Galaxy A55 5G | C9: 66 | D9: 25 | E9: 28
A10: Samsung | B10: Galaxy A25 5G | C10: 49 | D10: 10 | E10: 18
A11: Samsung | B11: Galaxy A15 5G | C11: 27 | D11: 18 | E11: 11

Sheet Puhelin Hinta
A1: Maker | B1: Model | C1: Average Price (EUR)
A2: Apple | B2: iPhone 15 Pro 5G | C2: 1179
A3: Apple | B3: iPhone 13 5G | C3: 479
A4: Honor | B4: X6a | C4: 117
A5: OnePlus | B5: Nord CE4 Lite 5G | C5: 179
A6: OnePlus | B6: Nord CE 3 Lite 5G | C6: 249
A7: OnePlus | B7: 12 5G | C7: 649
A8: Oppo | B8: A18 | C8: 79
A9: Samsung | B9: Galaxy A55 5G | C9: 299
A10: Samsung | B10: Galaxy A25 5G | C10: 169
A11: Samsung | B11: Galaxy A15 5G | C11: 129

Sheet Älykello merkki ja malli
A1: Merkki | B1: Malli
A2: Xplora | B2: Watch XGO3 4G – lasten kellopuhelin
A3: Xplora | B3: Watch XGO3 4G – lasten kellopuhelin
A4: Xplora | B4: Watch XGO3 4G – lasten kellopuhelin
A5: Apple | B5: Watch Series 9 GPS + Cellular
A6: Apple | B6: Watch Series 9 GPS + Cellular
A7: Apple | B7: Watch Series 9 GPS + Cellular
A8: Apple | B8: Watch SE GPS
A9: Apple | B9: Watch SE GPS
A10: Apple | B10: Watch SE GPS
A11: OnePlus | B11: Watch 2
A12: OnePlus | B12: Watch 2
... A16: Huawei | B16: Watch Fit 3

Sheet Älykello tuotehinta
A1: Model | B1: Näyttö | C1: Akku | D1: Takalasi
A2: Watch XGO3 4G – lasten kellopuhelin | B2: 40 | C2: 24 | D2: 11
A3: Watch Series 9 GPS + Cellular | B3: 230 | C3: 85 | D3: 65
A4: Watch SE GPS | B4: 100 | C4: 73 | D4: 25
A5: Watch 2 | B5: 64 | C5: 18 | D5: 13
A6: Watch Fit 3 | B6: 52 | C6: 8 | D6: 34

Sheet Älykellon Hinta
A1: Merkki | B1: Malli | C1: Hinta
A2: Xplora | B2: Watch XGO3 4G – lasten kellopuhelin | C2: 134
A3: Apple | B3: Watch Series 9 GPS + Cellular | C3: 575
A4: Apple | B4: Watch SE GPS | C4: 275
A5: Oneplus | B5: Watch 2 | C5: 254
A6: Huawei | B6: Watch Fit 3 | C6: 137

Sheet DataPuhelimista
A1: ID | B1: Liike | C1: Merkki | D1: Malli | E1: Merkki ja malli | F1: Liike sekä merkki ja malli | G1: Tuote | H1: Korjauksenhinta€ | I1: Tuotehinta € | J1: Puhelimenhinta € | K1: Vakuutuksen kesto kk | L1: Korjauksen kesto tunneissa | M1: Alkuperäinen osa true/false | P1: Datan lähde: myydyimmät puhelimet 2024
A2: =ROW(A2) - 1 -> 1 | B2: Fonum | C2: Apple | D2: iPhone 13 5G | E2: =Table1[[#This Row],[Merkki]] & " " & Table1[[#This Row],[Malli]] -> Apple iPhone 13 5G | F2: =Table1[[#This Row],[Liike]] & " " & Table1[[#This Row],[Merkki ja malli]] -> Fonum Apple iPhone 13 5G | G2: Näyttö | H2: 299 | I2: {=_xlfn.XLOOKUP(Table1[[#This Row],[Malli]],'Puhelin tuotehinta'!$B$2:$B$49,_xlfn.XLOOKUP(Table1[[#This Row],[Tuote]],'Puhelin tuotehinta'!$C$1:$E$1,'Puhelin tuotehinta'!$C$2:$E$49))} -> 181 | J2: =_xlfn.XLOOKUP(Table1[[#This Row],[Malli]],Table3[Model],Table3[Average Price (EUR)]) -> 479 | K2: 24 | L2: 1 | M2: FALSE
A3: =ROW(A3) - 1 -> 2 | B3: Fonum | C3: Apple | D3: iPhone 13 5G | E3: =Table1[[#This Row],[Merkki]] & " " & Table1[[#This Row],[Malli]] -> Apple iPhone 13 5G | F3: =Table1[[#This Row],[Liike]] & " " & Table1[[#This Row],[Merkki ja malli]] -> Fonum Apple iPhone 13 5G | G3: Akku | H3: 79 | I3: {=_xlfn.XLOOKUP(Table1[[#This Row],[Malli]],'Puhelin tuotehinta'!$B$2:$B$49,_xlfn.XLOOKUP(Table1[[#This Row],[Tuote]],'Puhelin tuotehinta'!$C$1:$E$1,'Puhelin tuotehinta'!$C$2:$E$49))} -> 27 | J3: =_xlfn.XLOOKUP(Table1[[#This Row],[Malli]],Table3[Model],Table3[Average Price (EUR)]) -> 479 | K3: 12 | L3: 1 | M3: FALSE | P3: Jos rivi on merkitty keltaisella, kysy haastattelun aikana
A4: =ROW(A4) - 1 -> 3 | B4: Fonum | C4: Apple | D4: iPhone 13 5G | E4: =Table1[[#This Row],[Merkki]] & " " & Table1[[#This Row],[Malli]] -> Apple iPhone 13 5G | F4: =Table1[[#This Row],[Liike]] & " " & Table1[[#This Row],[Merkki ja malli]] -> Fonum Apple iPhone 13 5G | G4: Latausportti | I4: {=_xlfn.XLOOKUP(Table1[[#This Row],[Malli]],'Puhelin tuotehinta'!$B$2:$B$49,_xlfn.XLOOKUP(Table1[[#This Row],[Tuote]],'Puhelin tuotehinta'!$C$1:$E$1,'Puhelin tuotehinta'!$C$2:$E$49))} -> 21 | J4: =_xlfn.XLOOKUP(Table1[[#This Row],[Malli]],Table3[Model],Table3[Average Price (EUR)]) -> 479 | K4: 24 | L4: 3 | M4: FALSE
A5: =ROW(A5) - 1 -> 4 | B5: Fonum | C5: Apple | D5: iPhone 15 Pro 5G | E5: =Table1[[#This Row],[Merkki]] & " " & Table1[[#This Row],[Malli]] -> Apple iPhone 15 Pro 5G | F5: =Table1[[#This Row],[Liike]] & " " & Table1[[#This Row],[Merkki ja malli]] -> Fonum Apple iPhone 15 Pro 5G | G5: Näyttö | H5: 489 | I5: {=_xlfn.XLOOKUP(Table1[[#This Row],[Malli]],'Puhelin tuotehinta'!$B$2:$B$49,_xlfn.XLOOKUP(Table1[[#This Row],[Tuote]],'Puhelin tuotehinta'!$C$1:$E$1,'Puhelin tuotehinta'!$C$2:$E$49))} -> 330 | J5: =_xlfn.XLOOKUP(Table1[[#This Row],[Malli]],Table3[Model],Table3[Average Price (EUR)]) -> 1179 | K5: 24 | L5: 1 | M5: FALSE
A6: =ROW(A6) - 1 -> 5 | B6: Fonum | C6: Apple | D6: iPhone 15 Pro 5G | E6: =Table1[[#This Row],[Merkki]] & " " & Table1[[#This Row],[Malli]] -> Apple iPhone 15 Pro 5G | F6: =Table1[[#This Row],[Liike]] & " " & Table1[[#This Row],[Merkki ja malli]] -> Fonum Apple iPhone 15 Pro 5G | G6: Akku | H6: 79 | I6: {=_xlfn.XLOOKUP(Table1[[#This Row],[Malli]],'Puhelin tuotehinta'!$B$2:$B$49,_xlfn.XLOOKUP(Table1[[#This Row],[Tuote]],'Puhelin tuotehinta'!$C$1:$E$1,'Puhelin tuotehinta'!$C$2:$E$49))} -> 27 | J6: =_xlfn.XLOOKUP(Table1[[#This Row],[Malli]],Table3[Model],Table3[Average Price (EUR)]) -> 1179 | K6: 12 | L6: 1 | M6: FALSE
A7: =ROW(A7) - 1 -> 6 | B7: Fonum | C7: Apple | D7: iPhone 15 Pro 5G | E7: =Table1[[#This Row],[Merkki]] & " " & Table1[[#This Row],[Malli]] -> Apple iPhone 15 Pro 5G | F7: =Table1[[#This Row],[Liike]] & " " & Table1[[#This Row],[Merkki ja malli]] -> Fonum Apple iPhone 15 Pro 5G | G7: Latausportti | I7: {=_xlfn.XLOOKUP(Table1[[#This Row],[Malli]],'Puhelin tuotehinta'!$B$2:$B$49,_xlfn.XLOOKUP(Table1[[#This Row],[Tuote]],'Puhelin tuotehinta'!$C$1:$E$1,'Puhelin tuotehinta'!$C$2:$E$49))} -> 38 | J7: =_xlfn.XLOOKUP(Table1[[#This Row],[Malli]],Table3[Model],Table3[Average Price (EUR)]) -> 1179 | K7: 24 | L7: 3 | M7: FALSE
A8: =ROW(A8) - 1 -> 7 | B8: Fonum | C8: Honor | D8: X6a | E8: =Table1[[#This Row],[Merkki]] & " " & Table1[[#This Row],[Malli]] -> Honor X6a | F8: =Table1[[#This Row],[Liike]] & " " & Table1[[#This Row],[Merkki ja malli]] -> Fonum Honor X6a | G8: Näyttö | H8: 79 | I8: {=_xlfn.XLOOKUP(Table1[[#This Row],[Malli]],'Puhelin tuotehinta'!$B$2:$B$49,_xlfn.XLOOKUP(Table1[[#This Row],[Tuote]],'Puhelin tuotehinta'!$C$1:$E$1,'Puhelin tuotehinta'!$C$2:$E$49))} -> 40 | J8: =_xlfn.XLOOKUP(Table1[[#This Row],[Malli]],Table3[Model],Table3[Average Price (EUR)]) -> 117 | K8: 24 | L8: 1 | M8: FALSE
A9: =ROW(A9) - 1 -> 8 | B9: Fonum | C9: Honor | D9: X6a | E9: =Table1[[#This Row],[Merkki]] & " " & Table1[[#This Row],[Malli]] -> Honor X6a | F9: =Table1[[#This Row],[Liike]] & " " & Table1[[#This Row],[Merkki ja malli]] -> Fonum Honor X6a | G9: Akku | I9: {=_xlfn.XLOOKUP(Table1[[#This Row],[Malli]],'Puhelin tuotehinta'!$B$2:$B$49,_xlfn.XLOOKUP(Table1[[#This Row],[Tuote]],'Puhelin tuotehinta'!$C$1:$E$1,'Puhelin tuotehinta'!$C$2:$E$49))} -> 19 | J9: =_xlfn.XLOOKUP(Table1[[#This Row],[Malli]],Table3[Model],Table3[Average Price (EUR)]) -> 117 | K9: 12 | L9: 1 | M9: FALSE
A10: =ROW(A10) - 1 -> 9 | B10: Fonum | C10: Honor | D10: X6a | E10: =Table1[[#This Row],[Merkki]] & " " & Table1[[#This Row],[Malli]] -> Honor X6a | F10: =Table1[[#This Row],[Liike]] & " " & Table1[[#This Row],[Merkki ja malli]] -> Fonum Honor X6a | G10: Latausportti | I10: {=_xlfn.XLOOKUP(Table1[[#This Row],[Malli]],'Puhelin tuotehinta'!$B$2:$B$49,_xlfn.XLOOKUP(Table1[[#This Row],[Tuote]],'Puhelin tuotehinta'!$C$1:$E$1,'Puhelin tuotehinta'!$C$2:$E$49))} -> 23 | J10: =_xlfn.XLOOKUP(Table1[[#This Row],[Malli]],Table3[Model],Table3[Average Price (EUR)]) -> 117 | K10: 24 | L10: 3 | M10: FALSE
A11: =ROW(A11) - 1 -> 10 | B11: Fonum | C11: OnePlus | D11: 12 5G | E11: =Table1[[#This Row],[Merkki]] & " " & Table1[[#This Row],[Malli]] -> OnePlus 12 5G | F11: =Table1[[#This Row],[Liike]] & " " & Table1[[#This Row],[Merkki ja malli]] -> Fonum OnePlus 12 5G | G11: Näyttö | H11: 429 € | I11: {=_xlfn.XLOOKUP(Table1[[#This Row],[Malli]],'Puhelin tuotehinta'!$B$2:$B$49,_xlfn.XLOOKUP(Table1[[#This Row],[Tuote]],'Puhelin tuotehinta'!$C$1:$E$1,'Puhelin tuotehinta'!$C$2:$E$49))} -> 176 | J11: =_xlfn.XLOOKUP(Table1[[#This Row],[Malli]],Table3[Model],Table3[Average Price (EUR)]) -> 649 | K11: 24 | L11: 1 | M11: FALSE
A12: =ROW(A12) - 1 -> 11 | B12: Fonum | C12: OnePlus | D12: 12 5G | E12: =Table1[[#This Row],[Merkki]] & " " & Table1[[#This Row],[Malli]] -> OnePlus 12 5G | F12: =Table1[[#This Row],[Liike]] & " " & Table1[[#This Row],[Merkki ja malli]] -> Fonum OnePlus 12 5G | G12: Akku | H12: 99 € | I12: {=_xlfn.XLOOKUP(Table1[[#This Row],[Malli]],'Puhelin tuotehinta'!$B$2:$B$49,_xlfn.XLOOKUP(Table1[[#This Row],[Tuote]],'Puhelin tuotehinta'!$C$1:$E$1,'Puhelin tuotehinta'!$C$2:$E$49))} -> 14 | J12: =_xlfn.XLOOKUP(Table1[[#This Row],[Malli]],Table3[Model],Table3[Average Price (EUR)]) -> 649 | K12: 12 | L12: 1 | M12: FALSE
A13: =ROW(A13) - 1 -> 12 | B13: Fonum | C13: OnePlus | D13: 12 5G | E13: =Table1[[#This Row],[Merkki]] & " " & Table1[[#This Row],[Malli]] -> OnePlus 12 5G | F13: =Table1[[#This Row],[Liike]] & " " & Table1[[#This Row],[Merkki ja malli]] -> Fonum OnePlus 12 5G | G13: Latausportti | I13: {=_xlfn.XLOOKUP(Table1[[#This Row],[Malli]],'Puhelin tuotehinta'!$B$2:$B$49,_xlfn.XLOOKUP(Table1[[#This Row],[Tuote]],'Puhelin tuotehinta'!$C$1:$E$1,'Puhelin tuotehinta'!$C$2:$E$49))} -> 15 | J13: =_xlfn.XLOOKUP(Table1[[#This Row],[Malli]],Table3[Model],Table3[Average Price (EUR)]) -> 649 | K13: 24 | L13: 3 | M13: FALSE
A14: =ROW(A14) - 1 -> 13 | B14: Fonum | C14: OnePlus | D14: Nord CE 3 Lite 5G | E14: =Table1[[#This Row],[Merkki]] & " " & Table1[[#This Row],[Malli]] -> OnePlus Nord CE 3 Lite 5G | F14: =Table1[[#This Row],[Liike]] & " " & Table1[[#This Row],[Merkki ja malli]] -> Fonum OnePlus Nord CE 3 Lite 5G | G14: Näyttö | H14: 119 € | I14: {=_xlfn.XLOOKUP(Table1[[#This Row],[Malli]],'Puhelin tuotehinta'!$B$2:$B$49,_xlfn.XLOOKUP(Table1[[#This Row],[Tuote]],'Puhelin tuotehinta'!$C$1:$E$1,'Puhelin tuotehinta'!$C$2:$E$49))} -> 40 | J14: =_xlfn.XLOOKUP(Table1[[#This Row],[Malli]],Table3[Model],Table3[Average Price (EUR)]) -> 249 | K14: 24 | L14: 1 | M14: FALSE
A15: =ROW(A15) - 1 -> 14 | B15: Fonum | C15: OnePlus | D15: Nord CE 3 Lite 5G | E15: =Table1[[#This Row],[Merkki]] & " " & Table1[[#This Row],[Malli]] -> OnePlus Nord CE 3 Lite 5G | F15: =Table1[[#This Row],[Liike]] & " " & Table1[[#This Row],[Merkki ja malli]] -> Fonum OnePlus Nord CE 3 Lite 5G | G15: Akku | H15: 79 € | I15: {=_xlfn.XLOOKUP(Table1[[#This Row],[Malli]],'Puhelin tuotehinta'!$B$2:$B$49,_xlfn.XLOOKUP(Table1[[#This Row],[Tuote]],'Puhelin tuotehinta'!$C$1:$E$1,'Puhelin tuotehinta'!$C$2:$E$49))} -> 10 | J15: =_xlfn.XLOOKUP(Table1[[#This Row],[Malli]],Table3[Model],Table3[Average Price (EUR)]) -> 249 | K15: 12 | L15: 1 | M15: FALSE
A16: =ROW(A16) - 1 -> 15 | B16: Fonum | C16: OnePlus | D16: Nord CE 3 Lite 5G | E16: =Table1[[#This Row],[Merkki]] & " " & Table1[[#This Row],[Malli]] -> OnePlus Nord CE 3 Lite 5G | F16: =Table1[[#This Row],[Liike]] & " " & Table1[[#This Row],[Merkki ja malli]] -> Fonum OnePlus Nord CE 3 Lite 5G | G16: Latausportti | I16: {=_xlfn.XLOOKUP(Table1[[#This Row],[Malli]],'Puhelin tuotehinta'!$B$2:$B$49,_xlfn.XLOOKUP(Table1[[#This Row],[Tuote]],'Puhelin tuotehinta'!$C$1:$E$1,'Puhelin tuotehinta'!$C$2:$E$49))} -> 15 | J16: =_xlfn.XLOOKUP(Table1[[#This Row],[Malli]],Table3[Model],Table3[Average Price (EUR)]) -> 249 | K16: 24 | L16: 3 | M16: FALSE
A17: =ROW(A17) - 1 -> 16 | B17: Fonum | C17: OnePlus | D17: Nord CE4 Lite 5G | E17: =Table1[[#This Row],[Merkki]] & " " & Table1[[#This Row],[Malli]] -> OnePlus Nord CE4 Lite 5G | F17: =Table1[[#This Row],[Liike]] & " " & Table1[[#This Row],[Merkki ja malli]] -> Fonum OnePlus Nord CE4 Lite 5G | G17: Näyttö | H17: 149 € | I17: {=_xlfn.XLOOKUP(Table1[[#This Row],[Malli]],'Puhelin tuotehinta'!$B$2:$B$49,_xlfn.XLOOKUP(Table1[[#This Row],[Tuote]],'Puhelin tuotehinta'!$C$1:$E$1,'Puhelin tuotehinta'!$C$2:$E$49))} -> 88 | J17: =_xlfn.XLOOKUP(Table1[[#This Row],[Malli]],Table3[Model],Table3[Average Price (EUR)]) -> 179 | K17: 24 | L17: 1 | M17: FALSE
A18: =ROW(A18) - 1 -> 17 | B18: Fonum | C18: OnePlus | D18: Nord CE4 Lite 5G | E18: =Table1[[#This Row],[Merkki]] & " " & Table1[[#This Row],[Malli]] -> OnePlus Nord CE4 Lite 5G | F18: =Table1[[#This Row],[Liike]] & " " & Table1[[#This Row],[Merkki ja malli]] -> Fonum OnePlus Nord CE4 Lite 5G | G18: Akku | I18: {=_xlfn.XLOOKUP(Table1[[#This Row],[Malli]],'Puhelin tuotehinta'!$B$2:$B$49,_xlfn.XLOOKUP(Table1[[#This Row],[Tuote]],'Puhelin tuotehinta'!$C$1:$E$1,'Puhelin tuotehinta'!$C$2:$E$49))} -> 12 | J18: =_xlfn.XLOOKUP(Table1[[#This Row],[Malli]],Table3[Model],Table3[Average Price (EUR)]) -> 179 | K18: 12 | L18: 1 | M18: FALSE
A19: =ROW(A19) - 1 -> 18 | B19: Fonum | C19: OnePlus | D19: Nord CE4 Lite 5G | E19: =Table1[[#This Row],[Merkki]] & " " & Table1[[#This Row],[Malli]] -> OnePlus Nord CE4 Lite 5G | F19: =Table1[[#This Row],[Liike]] & " " & Table1[[#This Row],[Merkki ja malli]] -> Fonum OnePlus Nord CE4 Lite 5G | G19: Latausportti | I19: {=_xlfn.XLOOKUP(Table1[[#This Row],[Malli]],'Puhelin tuotehinta'!$B$2:$B$49,_xlfn.XLOOKUP(Table1[[#This Row],[Tuote]],'Puhelin tuotehinta'!$C$1:$E$1,'Puhelin tuotehinta'!$C$2:$E$49))} -> 15 | J19: =_xlfn.XLOOKUP(Table1[[#This Row],[Malli]],Table3[Model],Table3[Average Price (EUR)]) -> 179 | K19: 24 | L19: 3 | M19: FALSE
A20: =ROW(A20) - 1 -> 19 | B20: Fonum | C20: Oppo | D20: A18 | E20: =Table1[[#This Row],[Merkki]] & " " & Table1[[#This Row],[Malli]] -> Oppo A18 | F20: =Table1[[#This Row],[Liike]] & " " & Table1[[#This Row],[Merkki ja malli]] -> Fonum Oppo A18 | G20: Näyttö | H20: 129 € | I20: {=_xlfn.XLOOKUP(Table1[[#This Row],[Malli]],'Puhelin tuotehinta'!$B$2:$B$49,_xlfn.XLOOKUP(Table1[[#This Row],[Tuote]],'Puhelin tuotehinta'!$C$1:$E$1,'Puhelin tuotehinta'!$C$2:$E$49))} -> 16 | J20: =_xlfn.XLOOKUP(Table1[[#This Row],[Malli]],Table3[Model],Table3[Average Price (EUR)]) -> 79 | K20: 24 | L20: 1 | M20: FALSE
A21: =ROW(A21) - 1 -> 20 | B21: Fonum | C21: Oppo | D21: A18 | E21: =Table1[[#This Row],[Merkki]] & " " & Table1[[#This Row],[Malli]] -> Oppo A18 | F21: =Table1[[#This Row],[Liike]] & " " & Table1[[#This Row],[Merkki ja malli]] -> Fonum Oppo A18 | G21: Akku | I21: {=_xlfn.XLOOKUP(Table1[[#This Row],[Malli]],'Puhelin tuotehinta'!$B$2:$B$49,_xlfn.XLOOKUP(Table1[[#This Row],[Tuote]],'Puhelin tuotehinta'!$C$1:$E$1,'Puhelin tuotehinta'!$C$2:$E$49))} -> 17 | J21: =_xlfn.XLOOKUP(Table1[[#This Row],[Malli]],Table3[Model],Table3[Average Price (EUR)]) -> 79 | K21: 12 | L21: 1 | M21: FALSE
A22: =ROW(A22) - 1 -> 21 | B22: Fonum | C22: Oppo | D22: A18 | E22: =Table1[[#This Row],[Merkki]] & " " & Table1[[#This Row],[Malli]] -> Oppo A18 | F22: =Table1[[#This Row],[Liike]] & " " & Table1[[#This Row],[Merkki ja malli]] -> Fonum Oppo A18 | G22: Latausportti | I22: {=_xlfn.XLOOKUP(Table1[[#This Row],[Malli]],'Puhelin tuotehinta'!$B$2:$B$49,_xlfn.XLOOKUP(Table1[[#This Row],[Tuote]],'Puhelin tuotehinta'!$C$1:$E$1,'Puhelin tuotehinta'!$C$2:$E$49))} -> 17 | J22: =_xlfn.XLOOKUP(Table1[[#This Row],[Malli]],Table3[Model],Table3[Average Price (EUR)]) -> 79 | K22: 24 | L22: 3 | M22: FALSE
A23: =ROW(A23) - 1 -> 22 | B23: Fonum | C23: Samsung | D23: Galaxy A15 5G | E23: =Table1[[#This Row],[Merkki]] & " " & Table1[[#This Row],[Malli]] -> Samsung Galaxy A15 5G | F23: =Table1[[#This Row],[Liike]] & " " & Table1[[#This Row],[Merkki ja malli]] -> Fonum Samsung Galaxy A15 5G | G23: Näyttö | H23: 99 € | I23: {=_xlfn.XLOOKUP(Table1[[#This Row],[Malli]],'Puhelin tuotehinta'!$B$2:$B$49,_xlfn.XLOOKUP(Table1[[#This Row],[Tuote]],'Puhelin tuotehinta'!$C$1:$E$1,'Puhelin tuotehinta'!$C$2:$E$49))} -> 27 | J23: =_xlfn.XLOOKUP(Table1[[#This Row],[Malli]],Table3[Model],Table3[Average Price (EUR)]) -> 129 | K23: 24 | L23: 1 | M23: FALSE
A24: =ROW(A24) - 1 -> 23 | B24: Fonum | C24: Samsung | D24: Galaxy A15 5G | E24: =Table1[[#This Row],[Merkki]] & " " & Table1[[#This Row],[Malli]] -> Samsung Galaxy A15 5G | F24: =Table1[[#This Row],[Liike]] & " " & Table1[[#This Row],[Merkki ja malli]] -> Fonum Samsung Galaxy A15 5G | G24: Akku | H24: 49 € | I24: {=_xlfn.XLOOKUP(Table1[[#This Row],[Malli]],'Puhelin tuotehinta'!$B$2:$B$49,_xlfn.XLOOKUP(Table1[[#This Row],[Tuote]],'Puhelin tuotehinta'!$C$1:$E$1,'Puhelin tuotehinta'!$C$2:$E$49))} -> 18 | J24: =_xlfn.XLOOKUP(Table1[[#This Row],[Malli]],Table3[Model],Table3[Average Price (EUR)]) -> 129 | K24: 12 | L24: 1 | M24: FALSE
A25: =ROW(A25) - 1 -> 24 | B25: Fonum | C25: Samsung | D25: Galaxy A15 5G | E25: =Table1[[#This Row],[Merkki]] & " " & Table1[[#This Row],[Malli]] -> Samsung Galaxy A15 5G | F25: =Table1[[#This Row],[Liike]] & " " & Table1[[#This Row],[Merkki ja malli]] -> Fonum Samsung Galaxy A15 5G | G25: Latausportti | I25: {=_xlfn.XLOOKUP(Table1[[#This Row],[Malli]],'Puhelin tuotehinta'!$B$2:$B$49,_xlfn.XLOOKUP(Table1[[#This Row],[Tuote]],'Puhelin tuotehinta'!$C$1:$E$1,'Puhelin tuotehinta'!$C$2:$E$49))} -> 11 | J25: =_xlfn.XLOOKUP(Table1[[#This Row],[Malli]],Table3[Model],Table3[Average Price (EUR)]) -> 129 | K25: 24 | L25: 3 | M25: FALSE
A26: =ROW(A26) - 1 -> 25 | B26: Fonum | C26: Samsung | D26: Galaxy A25 5G | E26: =Table1[[#This Row],[Merkki]] & " " & Table1[[#This Row],[Malli]] -> Samsung Galaxy A25 5G | F26: =Table1[[#This Row],[Liike]] & " " & Table1[[#This Row],[Merkki ja malli]] -> Fonum Samsung Galaxy A25 5G | G26: Näyttö | H26: 99 | I26: {=_xlfn.XLOOKUP(Table1[[#This Row],[Malli]],'Puhelin tuotehinta'!$B$2:$B$49,_xlfn.XLOOKUP(Table1[[#This Row],[Tuote]],'Puhelin tuotehinta'!$C$1:$E$1,'Puhelin tuotehinta'!$C$2:$E$49))} -> 49 | J26: =_xlfn.XLOOKUP(Table1[[#This Row],[Malli]],Table3[Model],Table3[Average Price (EUR)]) -> 169 | K26: 24 | L26: 1 | M26: FALSE
A27: =ROW(A27) - 1 -> 26 | B27: Fonum | C27: Samsung | D27: Galaxy A25 5G | E27: =Table1[[#This Row],[Merkki]] & " " & Table1[[#This Row],[Malli]] -> Samsung Galaxy A25 5G | F27: =Table1[[#This Row],[Liike]] & " " & Table1[[#This Row],[Merkki ja malli]] -> Fonum Samsung Galaxy A25 5G | G27: Akku | I27: {=_xlfn.XLOOKUP(Table1[[#This Row],[Malli]],'Puhelin tuotehinta'!$B$2:$B$49,_xlfn.XLOOKUP(Table1[[#This Row],[Tuote]],'Puhelin tuotehinta'!$C$1:$E$1,'Puhelin tuotehinta'!$C$2:$E$49))} -> 10 | J27: =_xlfn.XLOOKUP(Table1[[#This Row],[Malli]],Table3[Model],Table3[Average Price (EUR)]) -> 169 | K27: 12 | L27: 1 | M27: FALSE
A28: =ROW(A28) - 1 -> 27 | B28: Fonum | C28: Samsung | D28: Galaxy A25 5G | E28: =Table1[[#This Row],[Merkki]] & " " & Table1[[#This Row],[Malli]] -> Samsung Galaxy A25 5G | F28: =Table1[[#This Row],[Liike]] & " " & Table1[[#This Row],[Merkki ja malli]] -> Fonum Samsung Galaxy A25 5G | G28: Latausportti | I28: {=_xlfn.XLOOKUP(Table1[[#This Row],[Malli]],'Puhelin tuotehinta'!$B$2:$B$49,_xlfn.XLOOKUP(Table1[[#This Row],[Tuote]],'Puhelin tuotehinta'!$C$1:$E$1,'Puhelin tuotehinta'!$C$2:$E$49))} -> 18 | J28: =_xlfn.XLOOKUP(Table1[[#This Row],[Malli]],Table3[Model],Table3[Average Price (EUR)]) -> 169 | K28: 24 | L28: 3 | M28: FALSE
A29: =ROW(A29) - 1 -> 28 | B29: Fonum | C29: Samsung | D29: Galaxy A55 5G | E29: =Table1[[#This Row],[Merkki]] & " " & Table1[[#This Row],[Malli]] -> Samsung Galaxy A55 5G | F29: =Table1[[#This Row],[Liike]] & " " & Table1[[#This Row],[Merkki ja malli]] -> Fonum Samsung Galaxy A55 5G | G29: Näyttö | H29: 99 | I29: {=_xlfn.XLOOKUP(Table1[[#This Row],[Malli]],'Puhelin tuotehinta'!$B$2:$B$49,_xlfn.XLOOKUP(Table1[[#This Row],[Tuote]],'Puhelin tuotehinta'!$C$1:$E$1,'Puhelin tuotehinta'!$C$2:$E$49))} -> 66 | J29: =_xlfn.XLOOKUP(Table1[[#This Row],[Malli]],Table3[Model],Table3[Average Price (EUR)]) -> 299 | K29: 24 | L29: 1 | M29: FALSE
A30: =ROW(A30) - 1 -> 29 | B30: Fonum | C30: Samsung | D30: Galaxy A55 5G | E30: =Table1[[#This Row],[Merkki]] & " " & Table1[[#This Row],[Malli]] -> Samsung Galaxy A55 5G | F30: =Table1[[#This Row],[Liike]] & " " & Table1[[#This Row],[Merkki ja malli]] -> Fonum Samsung Galaxy A55 5G | G30: Akku | I30: {=_xlfn.XLOOKUP(Table1[[#This Row],[Malli]],'Puhelin tuotehinta'!$B$2:$B$49,_xlfn.XLOOKUP(Table1[[#This Row],[Tuote]],'Puhelin tuotehinta'!$C$1:$E$1,'Puhelin tuotehinta'!$C$2:$E$49))} -> 25 | J30: =_xlfn.XLOOKUP(Table1[[#This Row],[Malli]],Table3[Model],Table3[Average Price (EUR)]) -> 299 | K30: 12 | L30: 1 | M30: FALSE
A31: =ROW(A31) - 1 -> 30 | B31: Fonum | C31: Samsung | D31: Galaxy A55 5G | E31: =Table1[[#This Row],[Merkki]] & " " & Table1[[#This Row],[Malli]] -> Samsung Galaxy A55 5G | F31: =Table1[[#This Row],[Liike]] & " " & Table1[[#This Row],[Merkki ja malli]] -> Fonum Samsung Galaxy A55 5G | G31: Latausportti | I31: {=_xlfn.XLOOKUP(Table1[[#This Row],[Malli]],'Puhelin tuotehinta'!$B$2:$B$49,_xlfn.XLOOKUP(Table1[[#This Row],[Tuote]],'Puhelin tuotehinta'!$C$1:$E$1,'Puhelin tuotehinta'!$C$2:$E$49))} -> 28 | J31: =_xlfn.XLOOKUP(Table1[[#This Row],[Malli]],Table3[Model],Table3[Average Price (EUR)]) -> 299 | K31: 24 | L31: 3 | M31: FALSE
A32: =ROW(A32) - 1 -> 31 | B32: Handleit | C32: Apple | D32: iPhone 13 5G | E32: =Table1[[#This Row],[Merkki]] & " " & Table1[[#This Row],[Malli]] -> Apple iPhone 13 5G | F32: =Table1[[#This Row],[Liike]] & " " & Table1[[#This Row],[Merkki ja malli]] -> Handleit Apple iPhone 13 5G | G32: Näyttö | H32: 329 | I32: {=_xlfn.XLOOKUP(Table1[[#This Row],[Malli]],'Puhelin tuotehinta'!$B$2:$B$49,_xlfn.XLOOKUP(Table1[[#This Row],[Tuote]],'Puhelin tuotehinta'!$C$1:$E$1,'Puhelin tuotehinta'!$C$2:$E$49))} -> 181 | J32: =_xlfn.XLOOKUP(Table1[[#This Row],[Malli]],Table3[Model],Table3[Average Price (EUR)]) -> 479 | K32: 12 | L32: 1 | M32: TRUE
A33: =ROW(A33) - 1 -> 32 | B33: Handleit | C33: Apple | D33: iPhone 13 5G | E33: =Table1[[#This Row],[Merkki]] & " " & Table1[[#This Row],[Malli]] -> Apple iPhone 13 5G | F33: =Table1[[#This Row],[Liike]] & " " & Table1[[#This Row],[Merkki ja malli]] -> Handleit Apple iPhone 13 5G | G33: Akku | H33: 55 | I33: {=_xlfn.XLOOKUP(Table1[[#This Row],[Malli]],'Puhelin tuotehinta'!$B$2:$B$49,_xlfn.XLOOKUP(Table1[[#This Row],[Tuote]],'Puhelin tuotehinta'!$C$1:$E$1,'Puhelin tuotehinta'!$C$2:$E$49))} -> 27 | J33: =_xlfn.XLOOKUP(Table1[[#This Row],[Malli]],Table3[Model],Table3[Average Price (EUR)]) -> 479 | K33: 6 | L33: 1 | M33: FALSE
A34: =ROW(A34) - 1 -> 33 | B34: Handleit | C34: Apple | D34: iPhone 13 5G | E34: =Table1[[#This Row],[Merkki]] & " " & Table1[[#This Row],[Malli]] -> Apple iPhone 13 5G | F34: =Table1[[#This Row],[Liike]] & " " & Table1[[#This Row],[Merkki ja malli]] -> Handleit Apple iPhone 13 5G | G34: Latausportti | H34: 89 | I34: {=_xlfn.XLOOKUP(Table1[[#This Row],[Malli]],'Puhelin tuotehinta'!$B$2:$B$49,_xlfn.XLOOKUP(Table1[[#This Row],[Tuote]],'Puhelin tuotehinta'!$C$1:$E$1,'Puhelin tuotehinta'!$C$2:$E$49))} -> 21 | J34: =_xlfn.XLOOKUP(Table1[[#This Row],[Malli]],Table3[Model],Table3[Average Price (EUR)]) -> 479 | K34: 12 | L34: 2 | M34: FALSE
A35: =ROW(A35) - 1 -> 34 | B35: Handleit | C35: Apple | D35: iPhone 15 Pro 5G | E35: =Table1[[#This Row],[Merkki]] & " " & Table1[[#This Row],[Malli]] -> Apple iPhone 15 Pro 5G | F35: =Table1[[#This Row],[Liike]] & " " & Table1[[#This Row],[Merkki ja malli]] -> Handleit Apple iPhone 15 Pro 5G | G35: Latausportti | H35: 119 | I35: {=_xlfn.XLOOKUP(Table1[[#This Row],[Malli]],'Puhelin tuotehinta'!$B$2:$B$49,_xlfn.XLOOKUP(Table1[[#This Row],[Tuote]],'Puhelin tuotehinta'!$C$1:$E$1,'Puhelin tuotehinta'!$C$2:$E$49))} -> 38 | J35: =_xlfn.XLOOKUP(Table1[[#This Row],[Malli]],Table3[Model],Table3[Average Price (EUR)]) -> 1179 | K35: 12 | L35: 2 | M35: FALSE
A36: =ROW(A36) - 1 -> 35 | B36: Handleit | C36: Apple | D36: iPhone 15 Pro 5G | E36: =Table1[[#This Row],[Merkki]] & " " & Table1[[#This Row],[Malli]] -> Apple iPhone 15 Pro 5G | F36: =Table1[[#This Row],[Liike]] & " " & Table1[[#This Row],[Merkki ja malli]] -> Handleit Apple iPhone 15 Pro 5G | G36: Näyttö | H36: 479 | I36: {=_xlfn.XLOOKUP(Table1[[#This Row],[Malli]],'Puhelin tuotehinta'!$B$2:$B$49,_xlfn.XLOOKUP(Table1[[#This Row],[Tuote]],'Puhelin tuotehinta'!$C$1:$E$1,'Puhelin tuotehinta'!$C$2:$E$49))} -> 330 | J36: =_xlfn.XLOOKUP(Table1[[#This Row],[Malli]],Table3[Model],Table3[Average Price (EUR)]) -> 1179 | K36: 12 | L36: 1 | M36: TRUE
A37: =ROW(A37) - 1 -> 36 | B37: Handleit | C37: Apple | D37: iPhone 15 Pro 5G | E37: =Table1[[#This Row],[Merkki]] & " " & Table1[[#This Row],[Malli]] -> Apple iPhone 15 Pro 5G | F37: =Table1[[#This Row],[Liike]] & " " & Table1[[#This Row],[Merkki ja malli]] -> Handleit Apple iPhone 15 Pro 5G | G37: Akku | H37: 89 | I37: {=_xlfn.XLOOKUP(Table1[[#This Row],[Malli]],'Puhelin tuotehinta'!$B$2:$B$49,_xlfn.XLOOKUP(Table1[[#This Row],[Tuote]],'Puhelin tuotehinta'!$C$1:$E$1,'Puhelin tuotehinta'!$C$2:$E$49))} -> 27 | J37: =_xlfn.XLOOKUP(Table1[[#This Row],[Malli]],Table3[Model],Table3[Average Price (EUR)]) -> 1179 | K37: 6 | L37: 1 | M37: FALSE
A38: =ROW(A38) - 1 -> 37 | B38: Handleit | C38: Honor | D38: X6a | E38: =Table1[[#This Row],[Merkki]] & " " & Table1[[#This Row],[Malli]] -> Honor X6a | F38: =Table1[[#This Row],[Liike]] & " " & Table1[[#This Row],[Merkki ja malli]] -> Handleit Honor X6a | G38: Näyttö | H38: 99 | I38: {=_xlfn.XLOOKUP(Table1[[#This Row],[Malli]],'Puhelin tuotehinta'!$B$2:$B$49,_xlfn.XLOOKUP(Table1[[#This Row],[Tuote]],'Puhelin tuotehinta'!$C$1:$E$1,'Puhelin tuotehinta'!$C$2:$E$49))} -> 40 | J38: =_xlfn.XLOOKUP(Table1[[#This Row],[Malli]],Table3[Model],Table3[Average Price (EUR)]) -> 117 | K38: 12 | L38: 1
A39: =ROW(A39) - 1 -> 38 | B39: Handleit | C39: Honor | D39: X6a | E39: =Table1[[#This Row],[Merkki]] & " " & Table1[[#This Row],[Malli]] -> Honor X6a | F39: =Table1[[#This Row],[Liike]] & " " & Table1[[#This Row],[Merkki ja malli]] -> Handleit Honor X6a | G39: Akku | H39: 39 | I39: {=_xlfn.XLOOKUP(Table1[[#This Row],[Malli]],'Puhelin tuotehinta'!$B$2:$B$49,_xlfn.XLOOKUP(Table1[[#This Row],[Tuote]],'Puhelin tuotehinta'!$C$1:$E$1,'Puhelin tuotehinta'!$C$2:$E$49))} -> 19 | J39: =_xlfn.XLOOKUP(Table1[[#This Row],[Malli]],Table3[Model],Table3[Average Price (EUR)]) -> 117 | K39: 6 | L39: 1
A40: =ROW(A40) - 1 -> 39 | B40: Handleit | C40: Honor | D40: X6a | E40: =Table1[[#This Row],[Merkki]] & " " & Table1[[#This Row],[Malli]] -> Honor X6a | F40: =Table1[[#This Row],[Liike]] & " " & Table1[[#This Row],[Merkki ja malli]] -> Handleit Honor X6a | G40: Latausportti | I40: {=_xlfn.XLOOKUP(Table1[[#This Row],[Malli]],'Puhelin tuotehinta'!$B$2:$B$49,_xlfn.XLOOKUP(Table1[[#This Row],[Tuote]],'Puhelin tuotehinta'!$C$1:$E$1,'Puhelin tuotehinta'!$C$2:$E$49))} -> 23 | J40: =_xlfn.XLOOKUP(Table1[[#This Row],[Malli]],Table3[Model],Table3[Average Price (EUR)]) -> 117 | K40: 12 | L40: 2
...

Sheet DataÄlykelloista
A1: ID | B1: Liike | C1: Merkki | D1: Malli | E1: Merkki ja malli | F1: Liike sekä merkki ja malli | G1: Tuote | H1: Korjauksenhinta € | I1: Tuotehinta € | J1: Älykellonhinta € | K1: Vakuutuksen kesto kk | L1: Korjauksen kesto tunneissa | M1: Alkuperäinen osa true/false
A2: =ROW(A2) - 1 -> 1 | B2: Fonum | C2: Apple | D2: Watch SE GPS | E2: =Table4[[#This Row],[Merkki]] & " " & Table4[[#This Row],[Malli]] -> Apple Watch SE GPS | F2: =Table4[[#This Row],[Liike]] & " " & Table4[[#This Row],[Merkki ja malli]] -> Fonum Apple Watch SE GPS | G2: Näyttö | I2: {=_xlfn.XLOOKUP(Table4[[#This Row],[Malli]],'Älykello tuotehinta'!$A$2:$A$6,_xlfn.XLOOKUP(Table4[[#This Row],[Tuote]],'Älykello tuotehinta'!$B$1:$D$1,'Älykello tuotehinta'!$B$2:$D$6))} -> 100 | J2: =_xlfn.XLOOKUP(Table4[[#This Row],[Malli]],'Älykellon Hinta'!$B$2:$B$6,'Älykellon Hinta'!$C$2:$C$6) -> 275
A3: =ROW(A3) - 1 -> 2 | B3: Fonum | C3: Apple | D3: Watch SE GPS | E3: =Table4[[#This Row],[Merkki]] & " " & Table4[[#This Row],[Malli]] -> Apple Watch SE GPS | F3: =Table4[[#This Row],[Liike]] & " " & Table4[[#This Row],[Merkki ja malli]] -> Fonum Apple Watch SE GPS | G3: Akku | I3: {=_xlfn.XLOOKUP(Table4[[#This Row],[Malli]],'Älykello tuotehinta'!$A$2:$A$6,_xlfn.XLOOKUP(Table4[[#This Row],[Tuote]],'Älykello tuotehinta'!$B$1:$D$1,'Älykello tuotehinta'!$B$2:$D$6))} -> 73 | J3: =_xlfn.XLOOKUP(Table4[[#This Row],[Malli]],'Älykellon Hinta'!$B$2:$B$6,'Älykellon Hinta'!$C$2:$C$6) -> 275
A4: =ROW(A4) - 1 -> 3 | B4: Fonum | C4: Apple | D4: Watch SE GPS | E4: =Table4[[#This Row],[Merkki]] & " " & Table4[[#This Row],[Malli]] -> Apple Watch SE GPS | F4: =Table4[[#This Row],[Liike]] & " " & Table4[[#This Row],[Merkki ja malli]] -> Fonum Apple Watch SE GPS | G4: Takalasi | I4: {=_xlfn.XLOOKUP(Table4[[#This Row],[Malli]],'Älykello tuotehinta'!$A$2:$A$6,_xlfn.XLOOKUP(Table4[[#This Row],[Tuote]],'Älykello tuotehinta'!$B$1:$D$1,'Älykello tuotehinta'!$B$2:$D$6))} -> 25 | J4: =_xlfn.XLOOKUP(Table4[[#This Row],[Malli]],'Älykellon Hinta'!$B$2:$B$6,'Älykellon Hinta'!$C$2:$C$6) -> 275
A5: =ROW(A5) - 1 -> 4 | B5: Fonum | C5: Apple | D5: Watch Series 9 GPS + Cellular | E5: =Table4[[#This Row],[Merkki]] & " " & Table4[[#This Row],[Malli]] -> Apple Watch Series 9 GPS + Cellular | F5: =Table4[[#This Row],[Liike]] & " " & Table4[[#This Row],[Merkki ja malli]] -> Fonum Apple Watch Series 9 GPS + Cellular | G5: Näyttö | I5: {=_xlfn.XLOOKUP(Table4[[#This Row],[Malli]],'Älykello tuotehinta'!$A$2:$A$6,_xlfn.XLOOKUP(Table4[[#This Row],[Tuote]],'Älykello tuotehinta'!$B$1:$D$1,'Älykello tuotehinta'!$B$2:$D$6))} -> 230 | J5: =_xlfn.XLOOKUP(Table4[[#This Row],[Malli]],'Älykellon Hinta'!$B$2:$B$6,'Älykellon Hinta'!$C$2:$C$6) -> 575
A6: =ROW(A6) - 1 -> 5 | B6: Fonum | C6: Apple | D6: Watch Series 9 GPS + Cellular | E6: =Table4[[#This Row],[Merkki]] & " " & Table4[[#This Row],[Malli]] -> Apple Watch Series 9 GPS + Cellular | F6: =Table4[[#This Row],[Liike]] & " " & Table4[[#This Row],[Merkki ja malli]] -> Fonum Apple Watch Series 9 GPS + Cellular | G6: Akku | I6: {=_xlfn.XLOOKUP(Table4[[#This Row],[Malli]],'Älykello tuotehinta'!$A$2:$A$6,_xlfn.XLOOKUP(Table4[[#This Row],[Tuote]],'Älykello tuotehinta'!$B$1:$D$1,'Älykello tuotehinta'!$B$2:$D$6))} -> 85 | J6: =_xlfn.XLOOKUP(Table4[[#This Row],[Malli]],'Älykellon Hinta'!$B$2:$B$6,'Älykellon Hinta'!$C$2:$C$6) -> 575
A7: =ROW(A7) - 1 -> 6 | B7: Fonum | C7: Apple | D7: Watch Series 9 GPS + Cellular | E7: =Table4[[#This Row],[Merkki]] & " " & Table4[[#This Row],[Malli]] -> Apple Watch Series 9 GPS + Cellular | F7: =Table4[[#This Row],[Liike]] & " " & Table4[[#This Row],[Merkki ja malli]] -> Fonum Apple Watch Series 9 GPS + Cellular | G7: Takalasi | I7: {=_xlfn.XLOOKUP(Table4[[#This Row],[Malli]],'Älykello tuotehinta'!$A$2:$A$6,_xlfn.XLOOKUP(Table4[[#This Row],[Tuote]],'Älykello tuotehinta'!$B$1:$D$1,'Älykello tuotehinta'!$B$2:$D$6))} -> 65 | J7: =_xlfn.XLOOKUP(Table4[[#This Row],[Malli]],'Älykellon Hinta'!$B$2:$B$6,'Älykellon Hinta'!$C$2:$C$6) -> 575
A8: =ROW(A8) - 1 -> 7 | B8: Fonum | C8: Huawei | D8: Watch Fit 3 | E8: =Table4[[#This Row],[Merkki]] & " " & Table4[[#This Row],[Malli]] -> Huawei Watch Fit 3 | F8: =Table4[[#This Row],[Liike]] & " " & Table4[[#This Row],[Merkki ja malli]] -> Fonum Huawei Watch Fit 3 | G8: Näyttö | I8: {=_xlfn.XLOOKUP(Table4[[#This Row],[Malli]],'Älykello tuotehinta'!$A$2:$A$6,_xlfn.XLOOKUP(Table4[[#This Row],[Tuote]],'Älykello tuotehinta'!$B$1:$D$1,'Älykello tuotehinta'!$B$2:$D$6))} -> 52 | J8: =_xlfn.XLOOKUP(Table4[[#This Row],[Malli]],'Älykellon Hinta'!$B$2:$B$6,'Älykellon Hinta'!$C$2:$C$6) -> 137
A9: =ROW(A9) - 1 -> 8 | B9: Fonum | C9: Huawei | D9: Watch Fit 3 | E9: =Table4[[#This Row],[Merkki]] & " " & Table4[[#This Row],[Malli]] -> Huawei Watch Fit 3 | F9: =Table4[[#This Row],[Liike]] & " " & Table4[[#This Row],[Merkki ja malli]] -> Fonum Huawei Watch Fit 3 | G9: Akku | I9: {=_xlfn.XLOOKUP(Table4[[#This Row],[Malli]],'Älykello tuotehinta'!$A$2:$A$6,_xlfn.XLOOKUP(Table4[[#This Row],[Tuote]],'Älykello tuotehinta'!$B$1:$D$1,'Älykello tuotehinta'!$B$2:$D$6))} -> 8 | J9: =_xlfn.XLOOKUP(Table4[[#This Row],[Malli]],'Älykellon Hinta'!$B$2:$B$6,'Älykellon Hinta'!$C$2:$C$6) -> 137
A10: =ROW(A10) - 1 -> 9 | B10: Fonum | C10: Huawei | D10: Watch Fit 3 | E10: =Table4[[#This Row],[Merkki]] & " " & Table4[[#This Row],[Malli]] -> Huawei Watch Fit 3 | F10: =Table4[[#This Row],[Liike]] & " " & Table4[[#This Row],[Merkki ja malli]] -> Fonum Huawei Watch Fit 3 | G10: Takalasi | I10: {=_xlfn.XLOOKUP(Table4[[#This Row],[Malli]],'Älykello tuotehinta'!$A$2:$A$6,_xlfn.XLOOKUP(Table4[[#This Row],[Tuote]],'Älykello tuotehinta'!$B$1:$D$1,'Älykello tuotehinta'!$B$2:$D$6))} -> 34 | J10: =_xlfn.XLOOKUP(Table4[[#This Row],[Malli]],'Älykellon Hinta'!$B$2:$B$6,'Älykellon Hinta'!$C$2:$C$6) -> 137
A11: =ROW(A11) - 1 -> 10 | B11: Fonum | C11: OnePlus | D11: Watch 2 | E11: =Table4[[#This Row],[Merkki]] & " " & Table4[[#This Row],[Malli]] -> OnePlus Watch 2 | F11: =Table4[[#This Row],[Liike]] & " " & Table4[[#This Row],[Merkki ja malli]] -> Fonum OnePlus Watch 2 | G11: Näyttö | I11: {=_xlfn.XLOOKUP(Table4[[#This Row],[Malli]],'Älykello tuotehinta'!$A$2:$A$6,_xlfn.XLOOKUP(Table4[[#This Row],[Tuote]],'Älykello tuotehinta'!$B$1:$D$1,'Älykello tuotehinta'!$B$2:$D$6))} -> 64 | J11: =_xlfn.XLOOKUP(Table4[[#This Row],[Malli]],'Älykellon Hinta'!$B$2:$B$6,'Älykellon Hinta'!$C$2:$C$6) -> 254
A12: =ROW(A12) - 1 -> 11 | B12: Fonum | C12: OnePlus | D12: Watch 2 | E12: =Table4[[#This Row],[Merkki]] & " " & Table4[[#This Row],[Malli]] -> OnePlus Watch 2 | F12: =Table4[[#This Row],[Liike]] & " " & Table4[[#This Row],[Merkki ja malli]] -> Fonum OnePlus Watch 2 | G12: Akku | I12: {=_xlfn.XLOOKUP(Table4[[#This Row],[Malli]],'Älykello tuotehinta'!$A$2:$A$6,_xlfn.XLOOKUP(Table4[[#This Row],[Tuote]],'Älykello tuotehinta'!$B$1:$D$1,'Älykello tuotehinta'!$B$2:$D$6))} -> 18 | J12: =_xlfn.XLOOKUP(Table4[[#This Row],[Malli]],'Älykellon Hinta'!$B$2:$B$6,'Älykellon Hinta'!$C$2:$C$6) -> 254
A13: =ROW(A13) - 1 -> 12 | B13: Fonum | C13: OnePlus | D13: Watch 2 | E13: =Table4[[#This Row],[Merkki]] & " " & Table4[[#This Row],[Malli]] -> OnePlus Watch 2 | F13: =Table4[[#This Row],[Liike]] & " " & Table4[[#This Row],[Merkki ja malli]] -> Fonum OnePlus Watch 2 | G13: Takalasi | I13: {=_xlfn.XLOOKUP(Table4[[#This Row],[Malli]],'Älykello tuotehinta'!$A$2:$A$6,_xlfn.XLOOKUP(Table4[[#This Row],[Tuote]],'Älykello tuotehinta'!$B$1:$D$1,'Älykello tuotehinta'!$B$2:$D$6))} -> 13 | J13: =_xlfn.XLOOKUP(Table4[[#This Row],[Malli]],'Älykellon Hinta'!$B$2:$B$6,'Älykellon Hinta'!$C$2:$C$6) -> 254
... A16: =ROW(A16) - 1 -> 15 | B16: Fonum | C16: Xplora | D16: Watch XGO3 4G – lasten kellopuhelin | E16: =Table4[[#This Row],[Merkki]] & " " & Table4[[#This Row],[Malli]] -> Xplora Watch XGO3 4G – lasten kellopuhelin | F16: =Table4[[#This Row],[Liike]] & " " & Table4[[#This Row],[Merkki ja malli]] -> Fonum Xplora Watch XGO3 4G – lasten kellopuhelin | G16: Takalasi | I16: {=_xlfn.XLOOKUP(Table4[[#This Row],[Malli]],'Älykello tuotehinta'!$A$2:$A$6,_xlfn.XLOOKUP(Table4[[#This Row],[Tuote]],'Älykello tuotehinta'!$B$1:$D$1,'Älykello tuotehinta'!$B$2:$D$6))} -> 11 | J16: =_xlfn.XLOOKUP(Table4[[#This Row],[Malli]],'Älykellon Hinta'!$B$2:$B$6,'Älykellon Hinta'!$C$2:$C$6) -> 134
A17: =ROW(A17) - 1 -> 16 | B17: Handleit | C17: Apple | D17: Watch SE GPS | E17: =Table4[[#This Row],[Merkki]] & " " & Table4[[#This Row],[Malli]] -> Apple Watch SE GPS | F17: =Table4[[#This Row],[Liike]] & " " & Table4[[#This Row],[Merkki ja malli]] -> Handleit Apple Watch SE GPS | G17: Näyttö | H17: 189 | I17: {=_xlfn.XLOOKUP(Table4[[#This Row],[Malli]],'Älykello tuotehinta'!$A$2:$A$6,_xlfn.XLOOKUP(Table4[[#This Row],[Tuote]],'Älykello tuotehinta'!$B$1:$D$1,'Älykello tuotehinta'!$B$2:$D$6))} -> 100 | J17: =_xlfn.XLOOKUP(Table4[[#This Row],[Malli]],'Älykellon Hinta'!$B$2:$B$6,'Älykellon Hinta'!$C$2:$C$6) -> 275 | K17: 24 | M17: FALSE
A18: =ROW(A18) - 1 -> 17 | B18: Handleit | C18: Apple | D18: Watch SE GPS | E18: =Table4[[#This Row],[Merkki]] & " " & Table4[[#This Row],[Malli]] -> Apple Watch SE GPS | F18: =Table4[[#This Row],[Liike]] & " " & Table4[[#This Row],[Merkki ja malli]] -> Handleit Apple Watch SE GPS | G18: Akku | H18: 99 | I18: {=_xlfn.XLOOKUP(Table4[[#This Row],[Malli]],'Älykello tuotehinta'!$A$2:$A$6,_xlfn.XLOOKUP(Table4[[#This Row],[Tuote]],'Älykello tuotehinta'!$B$1:$D$1,'Älykello tuotehinta'!$B$2:$D$6))} -> 73 | J18: =_xlfn.XLOOKUP(Table4[[#This Row],[Malli]],'Älykellon Hinta'!$B$2:$B$6,'Älykellon Hinta'!$C$2:$C$6) -> 275 | K18: 6 | M18: FALSE
A19: =ROW(A19) - 1 -> 18 | B19: Handleit | C19: Apple | D19: Watch SE GPS | E19: =Table4[[#This Row],[Merkki]] & " " & Table4[[#This Row],[Malli]] -> Apple Watch SE GPS | F19: =Table4[[#This Row],[Liike]] & " " & Table4[[#This Row],[Merkki ja malli]] -> Handleit Apple Watch SE GPS | G19: Takalasi | H19: 199 | I19: {=_xlfn.XLOOKUP(Table4[[#This Row],[Malli]],'Älykello tuotehinta'!$A$2:$A$6,_xlfn.XLOOKUP(Table4[[#This Row],[Tuote]],'Älykello tuotehinta'!$B$1:$D$1,'Älykello tuotehinta'!$B$2:$D$6))} -> 25 | J19: =_xlfn.XLOOKUP(Table4[[#This Row],[Malli]],'Älykellon Hinta'!$B$2:$B$6,'Älykellon Hinta'!$C$2:$C$6) -> 275 | K19: 24 | M19: FALSE
A20: =ROW(A20) - 1 -> 19 | B20: Handleit | C20: Apple | D20: Watch Series 9 GPS + Cellular | E20: =Table4[[#This Row],[Merkki]] & " " & Table4[[#This Row],[Malli]] -> Apple Watch Series 9 GPS + Cellular | F20: =Table4[[#This Row],[Liike]] & " " & Table4[[#This Row],[Merkki ja malli]] -> Handleit Apple Watch Series 9 GPS + Cellular | G20: Näyttö | H20: 299 | I20: {=_xlfn.XLOOKUP(Table4[[#This Row],[Malli]],'Älykello tuotehinta'!$A$2:$A$6,_xlfn.XLOOKUP(Table4[[#This Row],[Tuote]],'Älykello tuotehinta'!$B$1:$D$1,'Älykello tuotehinta'!$B$2:$D$6))} -> 230 | J20: =_xlfn.XLOOKUP(Table4[[#This Row],[Malli]],'Älykellon Hinta'!$B$2:$B$6,'Älykellon Hinta'!$C$2:$C$6) -> 575 | K20: 24 | M20: FALSE
A21: =ROW(A21) - 1 -> 20 | B21: Handleit | C21: Apple | D21: Watch Series 9 GPS + Cellular | E21: =Table4[[#This Row],[Merkki]] & " " & Table4[[#This Row],[Malli]] -> Apple Watch Series 9 GPS + Cellular | F21: =Table4[[#This Row],[Liike]] & " " & Table4[[#This Row],[Merkki ja malli]] -> Handleit Apple Watch Series 9 GPS + Cellular | G21: Akku | H21: 99 | I21: {=_xlfn.XLOOKUP(Table4[[#This Row],[Malli]],'Älykello tuotehinta'!$A$2:$A$6,_xlfn.XLOOKUP(Table4[[#This Row],[Tuote]],'Älykello tuotehinta'!$B$1:$D$1,'Älykello tuotehinta'!$B$2:$D$6))} -> 85 | J21: =_xlfn.XLOOKUP(Table4[[#This Row],[Malli]],'Älykellon Hinta'!$B$2:$B$6,'Älykellon Hinta'!$C$2:$C$6) -> 575 | K21: 6 | M21: FALSE
A22: =ROW(A22) - 1 -> 21 | B22: Handleit | C22: Apple | D22: Watch Series 9 GPS + Cellular | E22: =Table4[[#This Row],[Merkki]] & " " & Table4[[#This Row],[Malli]] -> Apple Watch Series 9 GPS + Cellular | F22: =Table4[[#This Row],[Liike]] & " " & Table4[[#This Row],[Merkki ja malli]] -> Handleit Apple Watch Series 9 GPS + Cellular | G22: Takalasi | H22: 189 | I22: {=_xlfn.XLOOKUP(Table4[[#This Row],[Malli]],'Älykello tuotehinta'!$A$2:$A$6,_xlfn.XLOOKUP(Table4[[#This Row],[Tuote]],'Älykello tuotehinta'!$B$1:$D$1,'Älykello tuotehinta'!$B$2:$D$6))} -> 65 | J22: =_xlfn.XLOOKUP(Table4[[#This Row],[Malli]],'Älykellon Hinta'!$B$2:$B$6,'Älykellon Hinta'!$C$2:$C$6) -> 575 | K22: 24 | M22: FALSE
A23: =ROW(A23) - 1 -> 22 | B23: Handleit | C23: Huawei | D23: Watch Fit 3 | E23: =Table4[[#This Row],[Merkki]] & " " & Table4[[#This Row],[Malli]] -> Huawei Watch Fit 3 | F23: =Table4[[#This Row],[Liike]] & " " & Table4[[#This Row],[Merkki ja malli]] -> Handleit Huawei Watch Fit 3 | G23: Näyttö | I23: {=_xlfn.XLOOKUP(Table4[[#This Row],[Malli]],'Älykello tuotehinta'!$A$2:$A$6,_xlfn.XLOOKUP(Table4[[#This Row],[Tuote]],'Älykello tuotehinta'!$B$1:$D$1,'Älykello tuotehinta'!$B$2:$D$6))} -> 52 | J23: =_xlfn.XLOOKUP(Table4[[#This Row],[Malli]],'Älykellon Hinta'!$B$2:$B$6,'Älykellon Hinta'!$C$2:$C$6) -> 137
A24: =ROW(A24) - 1 -> 23 | B24: Handleit | C24: Huawei | D24: Watch Fit 3 | E24: =Table4[[#This Row],[Merkki]] & " " & Table4[[#This Row],[Malli]] -> Huawei Watch Fit 3 | F24: =Table4[[#This Row],[Liike]] & " " & Table4[[#This Row],[Merkki ja malli]] -> Handleit Huawei Watch Fit 3 | G24: Akku | I24: {=_xlfn.XLOOKUP(Table4[[#This Row],[Malli]],'Älykello tuotehinta'!$A$2:$A$6,_xlfn.XLOOKUP(Table4[[#This Row],[Tuote]],'Älykello tuotehinta'!$B$1:$D$1,'Älykello tuotehinta'!$B$2:$D$6))} -> 8 | J24: =_xlfn.XLOOKUP(Table4[[#This Row],[Malli]],'Älykellon Hinta'!$B$2:$B$6,'Älykellon Hinta'!$C$2:$C$6) -> 137
A25: =ROW(A25) - 1 -> 24 | B25: Handleit | C25: Huawei | D25: Watch Fit 3 | E25: =Table4[[#This Row],[Merkki]] & " " & Table4[[#This Row],[Malli]] -> Huawei Watch Fit 3 | F25: =Table4[[#This Row],[Liike]] & " " & Table4[[#This Row],[Merkki ja malli]] -> Handleit Huawei Watch Fit 3 | G25: Takalasi | I25: {=_xlfn.XLOOKUP(Table4[[#This Row],[Malli]],'Älykello tuotehinta'!$A$2:$A$6,_xlfn.XLOOKUP(Table4[[#This Row],[Tuote]],'Älykello tuotehinta'!$B$1:$D$1,'Älykello tuotehinta'!$B$2:$D$6))} -> 34 | J25: =_xlfn.XLOOKUP(Table4[[#This Row],[Malli]],'Älykellon Hinta'!$B$2:$B$6,'Älykellon Hinta'!$C$2:$C$6) -> 137
A26: =ROW(A26) - 1 -> 25 | B26: Handleit | C26: OnePlus | D26: Watch 2 | E26: =Table4[[#This Row],[Merkki]] & " " & Table4[[#This Row],[Malli]] -> OnePlus Watch 2 | F26: =Table4[[#This Row],[Liike]] & " " & Table4[[#This Row],[Merkki ja malli]] -> Handleit OnePlus Watch 2 | G26: Näyttö | I26: {=_xlfn.XLOOKUP(Table4[[#This Row],[Malli]],'Älykello tuotehinta'!$A$2:$A$6,_xlfn.XLOOKUP(Table4[[#This Row],[Tuote]],'Älykello tuotehinta'!$B$1:$D$1,'Älykello tuotehinta'!$B$2:$D$6))} -> 64 | J26: =_xlfn.XLOOKUP(Table4[[#This Row],[Malli]],'Älykellon Hinta'!$B$2:$B$6,'Älykellon Hinta'!$C$2:$C$6) -> 254
A27: =ROW(A27) - 1 -> 26 | B27: Handleit | C27: OnePlus | D27: Watch 2 | E27: =Table4[[#This Row],[Merkki]] & " " & Table4[[#This Row],[Malli]] -> OnePlus Watch 2 | F27: =Table4[[#This Row],[Liike]] & " " & Table4[[#This Row],[Merkki ja malli]] -> Handleit OnePlus Watch 2 | G27: Akku | I27: {=_xlfn.XLOOKUP(Table4[[#This Row],[Malli]],'Älykello tuotehinta'!$A$2:$A$6,_xlfn.XLOOKUP(Table4[[#This Row],[Tuote]],'Älykello tuotehinta'!$B$1:$D$1,'Älykello tuotehinta'!$B$2:$D$6))} -> 18 | J27: =_xlfn.XLOOKUP(Table4[[#This Row],[Malli]],'Älykellon Hinta'!$B$2:$B$6,'Älykellon Hinta'!$C$2:$C$6) -> 254
A28: =ROW(A28) - 1 -> 27 | B28: Handleit | C28: OnePlus | D28: Watch 2 | E28: =Table4[[#This Row],[Merkki]] & " " & Table4[[#This Row],[Malli]] -> OnePlus Watch 2 | F28: =Table4[[#This Row],[Liike]] & " " & Table4[[#This Row],[Merkki ja malli]] -> Handleit OnePlus Watch 2 | G28: Takalasi | I28: {=_xlfn.XLOOKUP(Table4[[#This Row],[Malli]],'Älykello tuotehinta'!$A$2:$A$6,_xlfn.XLOOKUP(Table4[[#This Row],[Tuote]],'Älykello tuotehinta'!$B$1:$D$1,'Älykello tuotehinta'!$B$2:$D$6))} -> 13 | J28: =_xlfn.XLOOKUP(Table4[[#This Row],[Malli]],'Älykellon Hinta'!$B$2:$B$6,'Älykellon Hinta'!$C$2:$C$6) -> 254
A29: =ROW(A29) - 1 -> 28 | B29: Handleit | C29: Xplora | D29: Watch XGO3 4G – lasten kellopuhelin | E29: =Table4[[#This Row],[Merkki]] & " " & Table4[[#This Row],[Malli]] -> Xplora Watch XGO3 4G – lasten kellopuhelin | F29: =Table4[[#This Row],[Liike]] & " " & Table4[[#This Row],[Merkki ja malli]] -> Handleit Xplora Watch XGO3 4G – lasten kellopuhelin | G29: Näyttö | I29: {=_xlfn.XLOOKUP(Table4[[#This Row],[Malli]],'Älykello tuotehinta'!$A$2:$A$6,_xlfn.XLOOKUP(Table4[[#This Row],[Tuote]],'Älykello tuotehinta'!$B$1:$D$1,'Älykello tuotehinta'!$B$2:$D$6))} -> 40 | J29: =_xlfn.XLOOKUP(Table4[[#This Row],[Malli]],'Älykellon Hinta'!$B$2:$B$6,'Älykellon Hinta'!$C$2:$C$6) -> 134
A30: =ROW(A30) - 1 -> 29 | B30: Handleit | C30: Xplora | D30: Watch XGO3 4G – lasten kellopuhelin | E30: =Table4[[#This Row],[Merkki]] & " " & Table4[[#This Row],[Malli]] -> Xplora Watch XGO3 4G – lasten kellopuhelin | F30: =Table4[[#This Row],[Liike]] & " " & Table4[[#This Row],[Merkki ja malli]] -> Handleit Xplora Watch XGO3 4G – lasten kellopuhelin | G30: Akku | I30: {=_xlfn.XLOOKUP(Table4[[#This Row],[Malli]],'Älykello tuotehinta'!$A$2:$A$6,_xlfn.XLOOKUP(Table4[[#This Row],[Tuote]],'Älykello tuotehinta'!$B$1:$D$1,'Älykello tuotehinta'!$B$2:$D$6))} -> 24 | J30: =_xlfn.XLOOKUP(Table4[[#This Row],[Malli]],'Älykellon Hinta'!$B$2:$B$6,'Älykellon Hinta'!$C$2:$C$6) -> 134
A31: =ROW(A31) - 1 -> 30 | B31: Handleit | C31: Xplora | D31: Watch XGO3 4G – lasten kellopuhelin | E31: =Table4[[#This Row],[Merkki]] & " " & Table4[[#This Row],[Malli]] -> Xplora Watch XGO3 4G – lasten kellopuhelin | F31: =Table4[[#This Row],[Liike]] & " " & Table4[[#This Row],[Merkki ja malli]] -> Handleit Xplora Watch XGO3 4G – lasten kellopuhelin | G31: Takalasi | I31: {=_xlfn.XLOOKUP(Table4[[#This Row],[Malli]],'Älykello tuotehinta'!$A$2:$A$6,_xlfn.XLOOKUP(Table4[[#This Row],[Tuote]],'Älykello tuotehinta'!$B$1:$D$1,'Älykello tuotehinta'!$B$2:$D$6))} -> 11 | J31: =_xlfn.XLOOKUP(Table4[[#This Row],[Malli]],'Älykellon Hinta'!$B$2:$B$6,'Älykellon Hinta'!$C$2:$C$6) -> 134
A32: =ROW(A32) - 1 -> 31 | B32: itapsa | C32: Apple | D32: Watch SE GPS | E32: =Table4[[#This Row],[Merkki]] & " " & Table4[[#This Row],[Malli]] -> Apple Watch SE GPS | F32: =Table4[[#This Row],[Liike]] & " " & Table4[[#This Row],[Merkki ja malli]] -> itapsa Apple Watch SE GPS | G32: Näyttö | I32: {=_xlfn.XLOOKUP(Table4[[#This Row],[Malli]],'Älykello tuotehinta'!$A$2:$A$6,_xlfn.XLOOKUP(Table4[[#This Row],[Tuote]],'Älykello tuotehinta'!$B$1:$D$1,'Älykello tuotehinta'!$B$2:$D$6))} -> 100 | J32: =_xlfn.XLOOKUP(Table4[[#This Row],[Malli]],'Älykellon Hinta'!$B$2:$B$6,'Älykellon Hinta'!$C$2:$C$6) -> 275
A33: =ROW(A33) - 1 -> 32 | B33: itapsa | C33: Apple | D33: Watch SE GPS | E33: =Table4[[#This Row],[Merkki]] & " " & Table4[[#This Row],[Malli]] -> Apple Watch SE GPS | F33: =Table4[[#This Row],[Liike]] & " " & Table4[[#This Row],[Merkki ja malli]] -> itapsa Apple Watch SE GPS | G33: Akku | I33: {=_xlfn.XLOOKUP(Table4[[#This Row],[Malli]],'Älykello tuotehinta'!$A$2:$A$6,_xlfn.XLOOKUP(Table4[[#This Row],[Tuote]],'Älykello tuotehinta'!$B$1:$D$1,'Älykello tuotehinta'!$B$2:$D$6))} -> 73 | J33: =_xlfn.XLOOKUP(Table4[[#This Row],[Malli]],'Älykellon Hinta'!$B$2:$B$6,'Älykellon Hinta'!$C$2:$C$6) -> 275
A34: =ROW(A34) - 1 -> 33 | B34: itapsa | C34: Apple | D34: Watch SE GPS | E34: =Table4[[#This Row],[Merkki]] & " " & Table4[[#This Row],[Malli]] -> Apple Watch SE GPS | F34: =Table4[[#This Row],[Liike]] & " " & Table4[[#This Row],[Merkki ja malli]] -> itapsa Apple Watch SE GPS | G34: Takalasi | I34: {=_xlfn.XLOOKUP(Table4[[#This Row],[Malli]],'Älykello tuotehinta'!$A$2:$A$6,_xlfn.XLOOKUP(Table4[[#This Row],[Tuote]],'Älykello tuotehinta'!$B$1:$D$1,'Älykello tuotehinta'!$B$2:$D$6))} -> 25 | J34: =_xlfn.XLOOKUP(Table4[[#This Row],[Malli]],'Älykellon Hinta'!$B$2:$B$6,'Älykellon Hinta'!$C$2:$C$6) -> 275
... A76: =ROW(A76) - 1 -> 75 | B76: Puhelinhuolto | C76: Xplora | D76: Watch XGO3 4G – lasten kellopuhelin | E76: =Table4[[#This Row],[Merkki]] & " " & Table4[[#This Row],[Malli]] -> Xplora Watch XGO3 4G – lasten kellopuhelin | F76: =Table4[[#This Row],[Liike]] & " " & Table4[[#This Row],[Merkki ja malli]] -> Puhelinhuolto Xplora Watch XGO3 4G – lasten kellopuhelin | G76: Takalasi | I76: {=_xlfn.XLOOKUP(Table4[[#This Row],[Malli]],'Älykello tuotehinta'!$A$2:$A$6,_xlfn.XLOOKUP(Table4[[#This Row],[Tuote]],'Älykello tuotehinta'!$B$1:$D$1,'Älykello tuotehinta'!$B$2:$D$6))} -> 11 | J76: =_xlfn.XLOOKUP(Table4[[#This Row],[Malli]],'Älykellon Hinta'!$B$2:$B$6,'Älykellon Hinta'!$C$2:$C$6) -> 134
